Workbook
Name 切片器_成交月份: #N/A
Name 切片器_区域: #N/A

Sheet 中间表数据
A1: 成交月份 | B1: 5
A3: 行标签 | C3: 行标签 | D3: 求和项:成交金额 | E3: 求和项:成交金额月环比 | F3: 求和项:成交客户数 | G3: 求和项:成交客户数月环比 | H3: 求和项:总客单价 | I3: 求和项:总客单价月环比
A4: 华东 | C4: 4 | D4: 8361888 | F4: 665 | H4: 12574.268
A5: 华南 | C5: 5 | D5: 16154830 | E5: 0.93195965 | F5: 1540 | G5: 1.3157895 | H5: 10490.149 | I5: -0.1657447
A6: 华西北 | C6: 6 | D6: 33674469 | E6: 1.084483 | F6: 3242 | G6: 1.1051948 | H6: 10386.943 | I6: -0.0098384191
A7: 总计 | C7: 总计 | D7: 58191187 | F7: 5447 | H7: 10683.163

Sheet 中间表-图表
A3: 行标签 | B3: 求和项:成交金额 | H3: 行标签 | I3: 求和项:成交客户数 | N3: 行标签 | O3: 求和项:总客单价
A4: 华东 | B4: 0.60162859 | H4: 华东 | I4: 0.61168831 | N4: 6期 | O4: 8624.3916
A5: 华南 | B5: 0.19979027 | H5: 华南 | I5: 0.19155844 | N5: 12期 | O5: 11741.557
A6: 华西北 | B6: 0.19858114 | H6: 华西北 | I6: 0.19675325 | N6: 18期 | O6: 11631.45
A7: 总计 | B7: 1 | H7: 总计 | I7: 1 | N7: 总计 | O7: 10490.149
A14: 区域 | B14: 省份 | C14: 求和项:成交金额 | D14: 求和项:成交客户数 | E14: 求和项:总客单价 | J14: 行标签 | K14: 求和项:成交金额月环比 | L14: 求和项:成交客户数月环比 | M14: 求和项:总客单价月环比
A15: 华东 | B15: 苏州 | C15: 2622091.9 | D15: 259 | E15: 10123.907 | J15: 华东
A16: 华东 | B16: 杭州 | C16: 2453590.1 | D16: 247 | E16: 9933.5633 | J16: 杭州
A17: 华东 | B17: 合肥 | C17: 1977254.2 | D17: 190 | E17: 10406.601 | J17: 4
A18: 华东 | B18: 上海 | C18: 1629742.6 | D18: 165 | E18: 9877.2276 | J18: 5 | K18: 0.44194713 | L18: 0.9296875 | M18: -0.25275614
A19: 华东 | B19: 南京 | C19: 1036528.8 | D19: 81 | E19: 12796.652 | J19: 6 | K19: 1.3825674 | L19: 1.2145749 | M19: 0.075857684
A20: 华南 | B20: 广州 | C20: 2806402 | D20: 254 | E20: 11048.827 | J20: 合肥
A21: 华南 | B21: 深圳 | C21: 421175.92 | D21: 41 | E21: 10272.583 | J21: 4
A22: 华西北 | B22: 北京 | C22: 1549098.3 | D22: 159 | E22: 9742.7564 | J22: 5 | K22: 1.0638903 | L22: 1.6388889 | M22: -0.21789422
A23: 华西北 | B23: 西安 | C23: 668899.02 | D23: 47 | E23: 14231.894 | J23: 6 | K23: 0.45524295 | L23: 0.52105263 | M23: -0.043265878
A24: 华西北 | B24: 成都 | C24: 565210.85 | D24: 54 | E24: 10466.868 | J24: 南京
A25: 华西北 | B25: 重庆 | C25: 424836.48 | D25: 43 | E25: 9879.9181 | J25: 5
J26: 6 | K26: 1.51568 | L26: 1.9382716 | M26: -0.14382318
J27: 上海
J28: 4
J29: 5 | K29: 0.28891611 | L29: 0.57142857 | M29: -0.17978066
J30: 6 | K30: 2.1221467 | L30: 2.0060606 | M30: 0.038617359
A31: 求和项:成交金额 | B31: 列标签 | J31: 苏州
A32: 行标签 | B32: 6期 | C32: 12期 | D32: 18期 | E32: 总计 | J32: 4
A33: 43952 | B33: 25001.08 | C33: 118634.61 | D33: 46500.46 | E33: 190136.15 | J33: 5 | K33: 0.51954621 | L33: 0.96212121 | M33: -0.22555946
A34: 43953 | B34: 72103.89 | C34: 87989.28 | D34: 40002.16 | E34: 200095.33 | J34: 6 | K34: 0.78190996 | L34: 0.76833977 | M34: 0.0076739734
A35: 43954 | B35: 87634.53 | C35: 111180.44 | D35: 61189.36 | E35: 260004.33 | J35: 华南
A36: 43955 | B36: 104888.31 | C36: 254208.76 | D36: 54001.34 | E36: 413098.41 | J36: 广州
A37: 43956 | B37: 100665.44 | C37: 215945.72 | D37: 50002.38 | E37: 366613.54 | J37: 4
A38: 43957 | B38: 214275.17 | C38: 177004.19 | D38: 59002.45 | E38: 450281.81 | J38: 5 | K38: 2.2796937 | L38: 2.4324324 | M38: -0.044498681
A39: 43958 | B39: 178460.58 | C39: 238507.01 | D39: 96002.74 | E39: 512970.33 | J39: 6 | K39: 0.74784056 | L39: 0.91732283 | M39: -0.088395271
A40: 43959 | B40: 167855.78 | C40: 171506.49 | D40: 143948.35 | E40: 483310.62 | J40: 南宁
A41: 43960 | B41: 212327.47 | C41: 283010.08 | D41: 88502.31 | E41: 583839.86 | J41: 6
A42: 43961 | B42: 160992.32 | C42: 135881.44 | D42: 116002.45 | E42: 412876.21 | J42: 深圳
A43: 43962 | B43: 140821.42 | C43: 173506.79 | D43: 129504.99 | E43: 443833.2 | J43: 4
A44: 43963 | B44: 75127.43 | C44: 152974.08 | D44: 38000.95 | E44: 266102.46 | J44: 5 | K44: 1.48474 | L44: 1.7333333 | M44: -0.090948798
A45: 43964 | B45: 118276.25 | C45: 177292.61 | D45: 86003.7 | E45: 381572.56 | J45: 6 | K45: 0.94902674 | L45: 1.097561 | M45: -0.070812834
A46: 43965 | B46: 140106.45 | C46: 189006.16 | D46: 108002.16 | E46: 437114.77 | J46: 华西北
A47: 43966 | B47: 215206.46 | C47: 340508.98 | D47: 181290.27 | E47: 737005.71 | J47: 北京
A48: 43967 | B48: 202005.9 | C48: 239005.37 | D48: 117166.59 | E48: 558177.86 | J48: 4
...

Sheet 源数据
A1: 成交日期 | B1: 销售工号 | C1: 产品 | D1: 成交客户数 | E1: 成交金额 | F1: 产品类型 | G1: 期数 | H1: 区域 | I1: 省份 | J1: 小组 | K1: 业务组 | L1: 职务类别 | M1: 客单价 | N1: 成交年份 | O1: 成交月份
A2: 43922 | B2: 1000000028 | C2: 借呗12期 | D2: 3 | E2: 55000.68 | F2: 借呗 | G2: 12期 | H2: 华东 | I2: 杭州 | J2: 二组 | K2: 杭州二组 | L2: 普通员工 | M2: 18333.56 | N2: 2020 | O2: 4
A3: 43922 | B3: 1000000029 | C3: 借呗12期 | D3: 2 | E3: 40000.49 | F3: 借呗 | G3: 12期 | H3: 华东 | I3: 杭州 | J3: 二组 | K3: 杭州二组 | L3: 普通员工 | M3: 20000.245 | N3: 2020 | O3: 4
A4: 43922 | B4: 1000000032 | C4: 借呗6期 | D4: 1 | E4: 22000.65 | F4: 借呗 | G4: 6期 | H4: 华东 | I4: 苏州 | J4: 一组 | K4: 苏州一组 | L4: 管理人员 | M4: 22000.65 | N4: 2020 | O4: 4
A5: 43922 | B5: 1000000031 | C5: 借呗12期 | D5: 1 | E5: 20000.75 | F5: 借呗 | G5: 12期 | H5: 华东 | I5: 杭州 | J5: 一组 | K5: 杭州一组 | L5: 管理人员 | M5: 20000.75 | N5: 2020 | O5: 4
A6: 43922 | B6: 1000000040 | C6: 借呗6期 | D6: 1 | E6: 20000.72 | F6: 借呗 | G6: 6期 | H6: 华西北 | I6: 北京 | J6: 四组 | K6: 北京四组 | L6: 管理人员 | M6: 20000.72 | N6: 2020 | O6: 4
A7: 43922 | B7: 1000000054 | C7: 借呗12期 | D7: 1 | E7: 20000.69 | F7: 借呗 | G7: 12期 | H7: 华东 | I7: 上海 | J7: 一组 | K7: 上海一组 | L7: 普通员工 | M7: 20000.69 | N7: 2020 | O7: 4
A8: 43922 | B8: 1000000035 | C8: 借呗12期 | D8: 1 | E8: 15000.57 | F8: 借呗 | G8: 12期 | H8: 华东 | I8: 苏州 | J8: 三组 | K8: 苏州三组 | L8: 普通员工 | M8: 15000.57 | N8: 2020 | O8: 4
A9: 43922 | B9: 1000000043 | C9: 借呗12期 | D9: 3 | E9: 14501.3 | F9: 借呗 | G9: 12期 | H9: 华西北 | I9: 成都 | J9: 一组 | K9: 成都一组 | L9: 普通员工 | M9: 4833.7667 | N9: 2020 | O9: 4
A10: 43922 | B10: 1000000031 | C10: 借呗6期 | D10: 1 | E10: 5000.64 | F10: 借呗 | G10: 6期 | H10: 华东 | I10: 杭州 | J10: 一组 | K10: 杭州一组 | L10: 管理人员 | M10: 5000.64 | N10: 2020 | O10: 4
A11: 43922 | B11: 1000000049 | C11: 借呗6期 | D11: 1 | E11: 5000.64 | F11: 借呗 | G11: 6期 | H11: 华东 | I11: 合肥 | J11: 一组 | K11: 合肥一组 | L11: 普通员工 | M11: 5000.64 | N11: 2020 | O11: 4
A12: 43922 | B12: 1000000050 | C12: 借呗18期 | D12: 1 | E12: 5000.19 | F12: 借呗 | G12: 18期 | H12: 华东 | I12: 合肥 | J12: 一组 | K12: 合肥一组 | L12: 普通员工 | M12: 5000.19 | N12: 2020 | O12: 4
A13: 43923 | B13: 1000000029 | C13: 借呗12期 | D13: 2 | E13: 20000.93 | F13: 借呗 | G13: 12期 | H13: 华东 | I13: 杭州 | J13: 二组 | K13: 杭州二组 | L13: 普通员工 | M13: 10000.465 | N13: 2020 | O13: 4
... A3989: 44012 | B3989: 1000020084 | C3989: 借呗12期 | D3989: 1 | E3989: 9999.98 | F3989: 借呗 | G3989: 12期 | H3989: 华南 | I3989: 深圳 | J3989: 一组 | K3989: 深圳一组 | L3989: 普通员工 | M3989: 9999.98 | N3989: 2020 | O3989: 6

Sheet Dashboard (2)
B1: ="XX公司"&中间表数据!$B$1&"月销售数据监控" -> XX公司5月销售数据监控
E4: 成交客单价
E5: =GETPIVOTDATA("求和项:总客单价",中间表数据!$C$3,"成交月份",中间表数据!$B$1) -> 10490.149
E6: =GETPIVOTDATA("求和项:总客单价月环比",中间表数据!$C$3,"成交月份",中间表数据!$B$1) -> -0.1657447
C7: 成交金额 | H7: 成交用户数
C8: =GETPIVOTDATA("求和项:成交金额",中间表数据!$C$3,"成交月份",中间表数据!$B$1) -> 16154830 | H8: =GETPIVOTDATA("求和项:成交客户数",中间表数据!$C$3,"成交月份",中间表数据!$B$1) -> 1540
C9: =GETPIVOTDATA("求和项:成交金额月环比",中间表数据!$C$3,"成交月份",中间表数据!$B$1) -> 0.93195965 | H9: =GETPIVOTDATA("求和项:成交客户数月环比",中间表数据!$C$3,"成交月份",中间表数据!$B$1) -> 1.3157895
B14: 省份成交明细
B15: 区域 | C15: 省份 | D15: 成交金额 | E15: 月环比 | F15: 成交客户数 | G15: 月环比 | H15: 客单价 | I15: 月环比
B16: ='中间表-图表'!A15 -> 华东 | C16: ='中间表-图表'!B15 -> 苏州 | D16: ='中间表-图表'!C15 -> 2622091.9 | E16: =IFERROR(GETPIVOTDATA("求和项:成交金额月环比",'中间表-图表'!$J$14,"区域",B16,"省份",C16,"成交月份",中间表数据!$B$1),"-") -> 0.51954621 | F16: ='中间表-图表'!D15 -> 259 | G16: =IFERROR(GETPIVOTDATA("求和项:成交客户数月环比",'中间表-图表'!$J$14,"区域",B16,"省份",C16,"成交月份",中间表数据!$B$1),"") -> 0.96212121 | H16: ='中间表-图表'!E15 -> 10123.907 | I16: =IFERROR(GETPIVOTDATA("求和项:总客单价月环比",'中间表-图表'!$J$14,"区域",B16,"省份",C16,"成交月份",中间表数据!$B$1),"") -> -0.22555946
B17: ='中间表-图表'!A16 -> 华东 | C17: ='中间表-图表'!B16 -> 杭州 | D17: ='中间表-图表'!C16 -> 2453590.1 | E17: =IFERROR(GETPIVOTDATA("求和项:成交金额月环比",'中间表-图表'!$J$14,"区域",B17,"省份",C17,"成交月份",中间表数据!$B$1),"") -> 0.44194713 | F17: ='中间表-图表'!D16 -> 247 | G17: =IFERROR(GETPIVOTDATA("求和项:成交客户数月环比",'中间表-图表'!$J$14,"区域",B17,"省份",C17,"成交月份",中间表数据!$B$1),"") -> 0.9296875 | H17: ='中间表-图表'!E16 -> 9933.5633 | I17: =IFERROR(GETPIVOTDATA("求和项:总客单价月环比",'中间表-图表'!$J$14,"区域",B17,"省份",C17,"成交月份",中间表数据!$B$1),"") -> -0.25275614
B18: ='中间表-图表'!A17 -> 华东 | C18: ='中间表-图表'!B17 -> 合肥 | D18: ='中间表-图表'!C17 -> 1977254.2 | E18: =IFERROR(GETPIVOTDATA("求和项:成交金额月环比",'中间表-图表'!$J$14,"区域",B18,"省份",C18,"成交月份",中间表数据!$B$1),"") -> 1.0638903 | F18: ='中间表-图表'!D17 -> 190 | G18: =IFERROR(GETPIVOTDATA("求和项:成交客户数月环比",'中间表-图表'!$J$14,"区域",B18,"省份",C18,"成交月份",中间表数据!$B$1),"") -> 1.6388889 | H18: ='中间表-图表'!E17 -> 10406.601 | I18: =IFERROR(GETPIVOTDATA("求和项:总客单价月环比",'中间表-图表'!$J$14,"区域",B18,"省份",C18,"成交月份",中间表数据!$B$1),"") -> -0.21789422
B19: ='中间表-图表'!A18 -> 华东 | C19: ='中间表-图表'!B18 -> 上海 | D19: ='中间表-图表'!C18 -> 1629742.6 | E19: =IFERROR(GETPIVOTDATA("求和项:成交金额月环比",'中间表-图表'!$J$14,"区域",B19,"省份",C19,"成交月份",中间表数据!$B$1),"") -> 0.28891611 | F19: ='中间表-图表'!D18 -> 165 | G19: =IFERROR(GETPIVOTDATA("求和项:成交客户数月环比",'中间表-图表'!$J$14,"区域",B19,"省份",C19,"成交月份",中间表数据!$B$1),"") -> 0.57142857 | H19: ='中间表-图表'!E18 -> 9877.2276 | I19: =IFERROR(GETPIVOTDATA("求和项:总客单价月环比",'中间表-图表'!$J$14,"区域",B19,"省份",C19,"成交月份",中间表数据!$B$1),"") -> -0.17978066
B20: ='中间表-图表'!A19 -> 华东 | C20: ='中间表-图表'!B19 -> 南京 | D20: ='中间表-图表'!C19 -> 1036528.8 | E20: =IFERROR(GETPIVOTDATA("求和项:成交金额月环比",'中间表-图表'!$J$14,"区域",B20,"省份",C20,"成交月份",中间表数据!$B$1),"") -> 0 | F20: ='中间表-图表'!D19 -> 81 | G20: =IFERROR(GETPIVOTDATA("求和项:成交客户数月环比",'中间表-图表'!$J$14,"区域",B20,"省份",C20,"成交月份",中间表数据!$B$1),"") -> 0 | H20: ='中间表-图表'!E19 -> 12796.652 | I20: =IFERROR(GETPIVOTDATA("求和项:总客单价月环比",'中间表-图表'!$J$14,"区域",B20,"省份",C20,"成交月份",中间表数据!$B$1),"") -> 0
B21: ='中间表-图表'!A20 -> 华南 | C21: ='中间表-图表'!B20 -> 广州 | D21: ='中间表-图表'!C20 -> 2806402 | E21: =IFERROR(GETPIVOTDATA("求和项:成交金额月环比",'中间表-图表'!$J$14,"区域",B21,"省份",C21,"成交月份",中间表数据!$B$1),"") -> 2.2796937 | F21: ='中间表-图表'!D20 -> 254 | G21: =IFERROR(GETPIVOTDATA("求和项:成交客户数月环比",'中间表-图表'!$J$14,"区域",B21,"省份",C21,"成交月份",中间表数据!$B$1),"") -> 2.4324324 | H21: ='中间表-图表'!E20 -> 11048.827 | I21: =IFERROR(GETPIVOTDATA("求和项:总客单价月环比",'中间表-图表'!$J$14,"区域",B21,"省份",C21,"成交月份",中间表数据!$B$1),"") -> -0.044498681
B22: ='中间表-图表'!A21 -> 华南 | C22: ='中间表-图表'!B21 -> 深圳 | D22: ='中间表-图表'!C21 -> 421175.92 | E22: =IFERROR(GETPIVOTDATA("求和项:成交金额月环比",'中间表-图表'!$J$14,"区域",B22,"省份",C22,"成交月份",中间表数据!$B$1),"") -> 1.48474 | F22: ='中间表-图表'!D21 -> 41 | G22: =IFERROR(GETPIVOTDATA("求和项:成交客户数月环比",'中间表-图表'!$J$14,"区域",B22,"省份",C22,"成交月份",中间表数据!$B$1),"") -> 1.7333333 | H22: ='中间表-图表'!E21 -> 10272.583 | I22: =IFERROR(GETPIVOTDATA("求和项:总客单价月环比",'中间表-图表'!$J$14,"区域",B22,"省份",C22,"成交月份",中间表数据!$B$1),"") -> -0.090948798
B23: ='中间表-图表'!A22 -> 华西北 | C23: ='中间表-图表'!B22 -> 北京 | D23: ='中间表-图表'!C22 -> 1549098.3 | E23: =IFERROR(GETPIVOTDATA("求和项:成交金额月环比",'中间表-图表'!$J$14,"区域",B23,"省份",C23,"成交月份",中间表数据!$B$1),"") -> 0.67783864 | F23: ='中间表-图表'!D22 -> 159 | G23: =IFERROR(GETPIVOTDATA("求和项:成交客户数月环比",'中间表-图表'!$J$14,"区域",B23,"省份",C23,"成交月份",中间表数据!$B$1),"") -> 1.1780822 | H23: ='中间表-图表'!E22 -> 9742.7564 | I23: =IFERROR(GETPIVOTDATA("求和项:总客单价月环比",'中间表-图表'!$J$14,"区域",B23,"省份",C23,"成交月份",中间表数据!$B$1),"") -> -0.22967157
B24: ='中间表-图表'!A23 -> 华西北 | C24: ='中间表-图表'!B23 -> 西安 | D24: ='中间表-图表'!C23 -> 668899.02 | E24: =IFERROR(GETPIVOTDATA("求和项:成交金额月环比",'中间表-图表'!$J$14,"区域",B24,"省份",C24,"成交月份",中间表数据!$B$1),"") -> 1.623073 | F24: ='中间表-图表'!D23 -> 47 | G24: =IFERROR(GETPIVOTDATA("求和项:成交客户数月环比",'中间表-图表'!$J$14,"区域",B24,"省份",C24,"成交月份",中间表数据!$B$1),"") -> 1.7647059 | H24: ='中间表-图表'!E23 -> 14231.894 | I24: =IFERROR(GETPIVOTDATA("求和项:总客单价月环比",'中间表-图表'!$J$14,"区域",B24,"省份",C24,"成交月份",中间表数据!$B$1),"") -> -0.051228904
B25: ='中间表-图表'!A24 -> 华西北 | C25: ='中间表-图表'!B24 -> 成都 | D25: ='中间表-图表'!C24 -> 565210.85 | E25: =IFERROR(GETPIVOTDATA("求和项:成交金额月环比",'中间表-图表'!$J$14,"区域",B25,"省份",C25,"成交月份",中间表数据!$B$1),"") -> 0.60109385 | F25: ='中间表-图表'!D24 -> 54 | G25: =IFERROR(GETPIVOTDATA("求和项:成交客户数月环比",'中间表-图表'!$J$14,"区域",B25,"省份",C25,"成交月份",中间表数据!$B$1),"") -> 0.45945946 | H25: ='中间表-图表'!E24 -> 10466.868 | I25: =IFERROR(GETPIVOTDATA("求和项:总客单价月环比",'中间表-图表'!$J$14,"区域",B25,"省份",C25,"成交月份",中间表数据!$B$1),"") -> 0.097045786
E26: =IFERROR(GETPIVOTDATA("求和项:成交金额月环比",'中间表-图表'!$J$14,"区域",B26,"省份",C26,"成交月份",中间表数据!$B$1),"")
B27: 区域成交趋势
B51: 产品成交明细
B52: 期数 | C52: 成交金额 | D52: 占比 | E52: 月环比 | F52: 成交客户数 | G52: 月环比 | H52: 客单价 | I52: 月环比
B53: =IF('中间表-图表'!A69<>0,'中间表-图表'!A69,"") -> 6期 | C53: =IF('中间表-图表'!B69<>0,'中间表-图表'!B69,"") -> 5243630.1 | D53: =IF('中间表-图表'!C69<>0,'中间表-图表'!C69,"") -> 0.3245859 | E53: =IFERROR(GETPIVOTDATA("求和项:成交金额月环比",'中间表-图表'!$G$68,"期数",B53,"成交月份",中间表数据!$B$1),"") -> 1.2812306 | F53: =IF('中间表-图表'!D69<>0,'中间表-图表'!D69,"") -> 608 | G53: =IFERROR(GETPIVOTDATA("求和项:成交客户数月环比",'中间表-图表'!$G$68,"期数",B53,"成交月份",中间表数据!$B$1),"") -> 1.7762557 | H53: =IF('中间表-图表'!E69<>0,'中间表-图表'!E69,"") -> 8624.3916 | I53: =IFERROR(GETPIVOTDATA("求和项:总客单价月环比",'中间表-图表'!$G$68,"期数",B53,"成交月份",中间表数据!$B$1),"") -> -0.17830674
B54: =IF('中间表-图表'!A70<>0,'中间表-图表'!A70,"") -> 12期 | C54: =IF('中间表-图表'!B70<>0,'中间表-图表'!B70,"") -> 7538079.5 | D54: =IF('中间表-图表'!C70<>0,'中间表-图表'!C70,"") -> 0.4666146 | E54: =IFERROR(GETPIVOTDATA("求和项:成交金额月环比",'中间表-图表'!$G$68,"期数",B54,"成交月份",中间表数据!$B$1),"") -> 0.931057 | F54: =IF('中间表-图表'!D70<>0,'中间表-图表'!D70,"") -> 642 | G54: =IFERROR(GETPIVOTDATA("求和项:成交客户数月环比",'中间表-图表'!$G$68,"期数",B54,"成交月份",中间表数据!$B$1),"") -> 1.1471572 | H54: =IF('中间表-图表'!E70<>0,'中间表-图表'!E70,"") -> 11741.557 | I54: =IFERROR(GETPIVOTDATA("求和项:总客单价月环比",'中间表-图表'!$G$68,"期数",B54,"成交月份",中间表数据!$B$1),"") -> -0.10064479
B55: =IF('中间表-图表'!A71<>0,'中间表-图表'!A71,"") -> 18期 | C55: =IF('中间表-图表'!B71<>0,'中间表-图表'!B71,"") -> 3373120.5 | D55: =IF('中间表-图表'!C71<>0,'中间表-图表'!C71,"") -> 0.2087995 | E55: =IFERROR(GETPIVOTDATA("求和项:成交金额月环比",'中间表-图表'!$G$68,"期数",B55,"成交月份",中间表数据!$B$1),"") -> 0.56185546 | F55: =IF('中间表-图表'!D71<>0,'中间表-图表'!D71,"") -> 290 | G55: =IFERROR(GETPIVOTDATA("求和项:成交客户数月环比",'中间表-图表'!$G$68,"期数",B55,"成交月份",中间表数据!$B$1),"") -> 0.97278912 | H55: =IF('中间表-图表'!E71<>0,'中间表-图表'!E71,"") -> 11631.45 | I55: =IFERROR(GETPIVOTDATA("求和项:总客单价月环比",'中间表-图表'!$G$68,"期数",B55,"成交月份",中间表数据!$B$1),"") -> -0.20830085
B56: =IF('中间表-图表'!A72<>0,'中间表-图表'!A72,"") | C56: =IF('中间表-图表'!B72<>0,'中间表-图表'!B72,"") | D56: =IF('中间表-图表'!C72<>0,'中间表-图表'!C72,"") | E56: =IFERROR(GETPIVOTDATA("求和项:成交金额月环比",'中间表-图表'!$G$68,"期数",B56,"成交月份",中间表数据!$B$1),"") | F56: =IF('中间表-图表'!D72<>0,'中间表-图表'!D72,"") | G56: =IFERROR(GETPIVOTDATA("求和项:成交客户数月环比",'中间表-图表'!$G$68,"期数",B56,"成交月份",中间表数据!$B$1),"") | H56: =IF('中间表-图表'!E72<>0,'中间表-图表'!E72,"") | I56: =IFERROR(GETPIVOTDATA("求和项:总客单价月环比",'中间表-图表'!$G$68,"期数",B56,"成交月份",中间表数据!$B$1),"")
B57: =IF('中间表-图表'!A73<>0,'中间表-图表'!A73,"") | C57: =IF('中间表-图表'!B73<>0,'中间表-图表'!B73,"") | D57: =IF('中间表-图表'!C73<>0,'中间表-图表'!C73,"") | E57: =IFERROR(GETPIVOTDATA("求和项:成交金额月环比",'中间表-图表'!$G$68,"期数",B57,"成交月份",中间表数据!$B$1),"") | F57: =IF('中间表-图表'!D73<>0,'中间表-图表'!D73,"") | G57: =IFERROR(GETPIVOTDATA("求和项:成交客户数月环比",'中间表-图表'!$G$68,"期数",B57,"成交月份",中间表数据!$B$1),"") | H57: =IF('中间表-图表'!E73<>0,'中间表-图表'!E73,"") | I57: =IFERROR(GETPIVOTDATA("求和项:总客单价月环比",'中间表-图表'!$G$68,"期数",B57,"成交月份",中间表数据!$B$1),"")
B58: =IF('中间表-图表'!A74<>0,'中间表-图表'!A74,"") | C58: =IF('中间表-图表'!B74<>0,'中间表-图表'!B74,"") | D58: =IF('中间表-图表'!C74<>0,'中间表-图表'!C74,"") | E58: =IFERROR(GETPIVOTDATA("求和项:成交金额月环比",'中间表-图表'!$G$68,"期数",B58,"成交月份",中间表数据!$B$1),"") | F58: =IF('中间表-图表'!D74<>0,'中间表-图表'!D74,"") | G58: =IFERROR(GETPIVOTDATA("求和项:成交客户数月环比",'中间表-图表'!$G$68,"期数",B58,"成交月份",中间表数据!$B$1),"") | H58: =IF('中间表-图表'!E74<>0,'中间表-图表'!E74,"") | I58: =IFERROR(GETPIVOTDATA("求和项:总客单价月环比",'中间表-图表'!$G$68,"期数",B58,"成交月份",中间表数据!$B$1),"")
B60: 产品成交趋势
